Workbook

Sheet FinalScoringQuestionList
A1: Evaluation Question | B1: ID | C1: Scoring Category | D1: Eliminated Prior to Manual Evaluation (Yes, No, Automated) | E1: Eliminated During Manual Evaluation (Yes, No, Automated, N/A) | F1: Final Validated Scoring Procedure (Questionnaire, Automated Script, Eliminated) | G1: Authoritative Data Sources (Map to output JSON) | H1: Column1 | I1: Programmatic Steps or Automated Function | J1: Justification for Elimination | K1: Final Notes
A2: Does the variant preserve the same ordered sequence of high-level steps as the control? | B2: 1.1 | C2: Behavior Chain Fidelity | D2: No | E2: Automated | F2: =IF(OR(D2="Yes",E2="Yes"),"Eliminated", IF(OR(D2="Automated",E2="Automated"),"Automated Script", IF(AND(D2="No",E2="No"),"Questionnaire",""))) -> Automated Script | G2: "step_id", "technique_id" | I2: technique_sequence_match | K2: Important to note that "high-level steps" is not the same as the same about of steps generally. In translating OS, it maybe the case that more than one action is needed per original step. Solve this by looking at the technique level for each step.
A3: Does the variant preserve the same logical dependencies between steps? | B3: 1.2 | C3: Behavior Chain Fidelity | D3: No | E3: No | F3: =IF(OR(D3="Yes",E3="Yes"),"Eliminated", IF(OR(D3="Automated",E3="Automated"),"Automated Script", IF(AND(D3="No",E3="No"),"Questionnaire",""))) -> Questionnaire | K3: Logical dependency tracking is difficult to record in JSON format. Can possibly add more detail to track hosts, files, and accesses which are required for each step.
A4: Does the variant preserve the same operator intent per step? | B4: 1.3 | C4: Behavior Chain Fidelity | D4: No | E4: Yes | F4: =IF(OR(D4="Yes",E4="Yes"),"Eliminated", IF(OR(D4="Automated",E4="Automated"),"Automated Script", IF(AND(D4="No",E4="No"),"Questionnaire",""))) -> Eliminated | J4: Insufficient detail about LLM reasoning regarding operator intent. | K4: "intermeidate_output" JSON field provides a start to understand "why" the LLM (or an operator) would chose a certain command. More thorough analysis is required on a plan level.
A5: Are any steps in the control missing in the variant? (No = pass) | B5: 1.4 | C5: Behavior Chain Fidelity | D5: Automated | E5: N/A | F5: =IF(OR(D5="Yes",E5="Yes"),"Eliminated", IF(OR(D5="Automated",E5="Automated"),"Automated Script", IF(AND(D5="No",E5="No"),"Questionnaire",""))) -> Automated Script | I5: missing_steps | K5: See note for 1.1 about step equivalence. Logic described in missing_step documentation on GitLab.
A6: Are any new steps present in the variant that are not in the control? (No = pass) | B6: 1.5 | C6: Behavior Chain Fidelity | D6: Automated | E6: N/A | F6: =IF(OR(D6="Yes",E6="Yes"),"Eliminated", IF(OR(D6="Automated",E6="Automated"),"Automated Script", IF(AND(D6="No",E6="No"),"Questionnaire",""))) -> Automated Script | I6: extra_steps | K6: See note for 1.1 about step equivalence. Logic described in extra_steps documentation on GitLab.
A7: Does the variant preserve the same start and end conditions as the control? | B7: 1.6 | C7: Behavior Chain Fidelity | D7: No | E7: Yes | F7: =IF(OR(D7="Yes",E7="Yes"),"Eliminated", IF(OR(D7="Automated",E7="Automated"),"Automated Script", IF(AND(D7="No",E7="No"),"Questionnaire",""))) -> Eliminated | J7: Insufficient detail about operating environment starting state and ending state. | K7: This question makes more sense in the context of a fully defined start state, or an actual execution of the procedures measuring differences between start and end state via automated or manual means.
A8: Does the variant preserve the same privilege context progression as the control? | B8: 1.7 | C8: Behavior Chain Fidelity | D8: No | E8: Automated | F8: =IF(OR(D8="Yes",E8="Yes"),"Eliminated", IF(OR(D8="Automated",E8="Automated"),"Automated Script", IF(AND(D8="No",E8="No"),"Questionnaire",""))) -> Automated Script | I8: privilege_progression_match | K8: This question resulted in the addition of the "execution_level" JSON field, which the script's logic relies on. Additional detail may be necessary to answer this question for more detailed contexts.
A9: Do all steps reference real, identifiable commands or tools available on the target platform? (OS-level tool) | B9: 2.1 | C9: Technical Realism | D9: No | E9: No | F9: =IF(OR(D9="Yes",E9="Yes"),"Eliminated", IF(OR(D9="Automated",E9="Automated"),"Automated Script", IF(AND(D9="No",E9="No"),"Questionnaire",""))) -> Questionnaire
A10: Are all command arguments, flags, and options valid for the referenced tool and execution context? (Tool-level arguments) | B10: 2.2 | C10: Technical Realism | D10: No | E10: No | F10: =IF(OR(D10="Yes",E10="Yes"),"Eliminated", IF(OR(D10="Automated",E10="Automated"),"Automated Script", IF(AND(D10="No",E10="No"),"Questionnaire",""))) -> Questionnaire | K10: If 2.1 fails (not referencing a real command), this question should also fail/be invalid.
A11: Does the procedure respect OS-specific constraints and permissions? | B11: 2.3 | C11: Technical Realism | D11: No | E11: No | F11: =IF(OR(D11="Yes",E11="Yes"),"Eliminated", IF(OR(D11="Automated",E11="Automated"),"Automated Script", IF(AND(D11="No",E11="No"),"Questionnaire",""))) -> Questionnaire
A12: Does the procedure avoid Windows-only constructs on non-Windows systems? | B12: 2.4 | C12: Technical Realism | D12: Automated | E12: No | F12: Questionnaire | K12: Attempted to automate, however more development is needed to enumerate "Windows-only constructs" at a machine level. Atuomated results used as scoring aid.
A13: Are privilege requirements stated or implied correctly? | B13: 2.5 | C13: Technical Realism | D13: No | E13: No | F13: =IF(OR(D13="Yes",E13="Yes"),"Eliminated", IF(OR(D13="Automated",E13="Automated"),"Automated Script", IF(AND(D13="No",E13="No"),"Questionnaire",""))) -> Questionnaire | K13: This also relies on the "execution_level" JSON field, and any reasoning by the LLM. Further prompt engineering may assist in getting this context from the LLM/examining its reasoning.
A14: Would this procedure execute successfully in a default environment? | B14: 2.5 | C14: Technical Realism | D14: Yes | E14: N/A | F14: =IF(OR(D14="Yes",E14="Yes"),"Eliminated", IF(OR(D14="Automated",E14="Automated"),"Automated Script", IF(AND(D14="No",E14="No"),"Questionnaire",""))) -> Eliminated | J14: Insufficient detail about what constitutes a "default environment". A "default environment" may also not be useful when entering a pre-existing operating environment.
A15: Does the output generate telemetry that can be used for detection? | B15: 3.0.01 | C15: Defensive Value | D15: Yes | E15: N/A | F15: =IF(OR(D15="Yes",E15="Yes"),"Eliminated", IF(OR(D15="Automated",E15="Automated"),"Automated Script", IF(AND(D15="No",E15="No"),"Questionnaire",""))) -> Eliminated | J15: Insufficient detail about defender detections. Current data equates evaluation to "can this activity be detected"/"is telemetry generated"
A16: Does the output enable evaluation of detection coverage? | B16: 3.0.02 | C16: Defensive Value | D16: Yes | E16: N/A | F16: =IF(OR(D16="Yes",E16="Yes"),"Eliminated", IF(OR(D16="Automated",E16="Automated"),"Automated Script", IF(AND(D16="No",E16="No"),"Questionnaire",""))) -> Eliminated | J16: Insufficient detail about defender detections. Current data equates evaluation to "can this activity be detected"/"is telemetry generated"
A17: Does the output help distinguish this behavior from benign activity? | B17: 3.0.03 | C17: Defensive Value | D17: Yes | E17: N/A | F17: =IF(OR(D17="Yes",E17="Yes"),"Eliminated", IF(OR(D17="Automated",E17="Automated"),"Automated Script", IF(AND(D17="No",E17="No"),"Questionnaire",""))) -> Eliminated | J17: Insufficient detail about what constitutes a "benign behavior" in an operating environment. By the nature of an emulation process, some procedures may be obviously malicious, while others may be designed with the intent of appearing benign.
A18: Does the output help distinguish this behavior from other adversaries? | B18: 3.0.04 | C18: Defensive Value | D18: Yes | E18: N/A | F18: =IF(OR(D18="Yes",E18="Yes"),"Eliminated", IF(OR(D18="Automated",E18="Automated"),"Automated Script", IF(AND(D18="No",E18="No"),"Questionnaire",""))) -> Eliminated | J18: Insufficient detail about procedures used by other adversaries that matter to defenders. Generally may not be important for emulation assessment purposes
A19: Does the output surface defender-relevant artifacts? | B19: 3.0.05 | C19: Defensive Value | D19: No | E19: Yes | F19: =IF(OR(D19="Yes",E19="Yes"),"Eliminated", IF(OR(D19="Automated",E19="Automated"),"Automated Script", IF(AND(D19="No",E19="No"),"Questionnaire",""))) -> Eliminated | J19: Insufficient detail about defender detections. Current data equates evaluation to "can this activity be detected"/"is telemetry generated"
A20: Does the output avoid producing misleading or confusing telemetry? | B20: 3.0.06 | C20: Defensive Value | D20: Yes | E20: N/A | F20: =IF(OR(D20="Yes",E20="Yes"),"Eliminated", IF(OR(D20="Automated",E20="Automated"),"Automated Script", IF(AND(D20="No",E20="No"),"Questionnaire",""))) -> Eliminated | J20: Insufficient detail about what constitutes a "misleading or confusing" telemetry in an operating environment. By the nature of an emulation process, some procedures may be intended to confuse or mislead (see 3.0.3). In these cases, this question may only be useful where the telemetry differs substantially from the original procedures.
A21: Do the variant and control map to the same parent ATT&CK technique IDs? | B21: 3.1.01 | C21: Telemetry Equivalence | D21: Automated | E21: N/A | F21: =IF(OR(D21="Yes",E21="Yes"),"Eliminated", IF(OR(D21="Automated",E21="Automated"),"Automated Script", IF(AND(D21="No",E21="No"),"Questionnaire",""))) -> Automated Script | I21: parent_technique_ids_match
A22: Do the variant and control map to the same ATT&CK sub-technique IDs (Exact)? | B22: 3.1.02 | C22: Telemetry Equivalence | D22: Automated | E22: N/A | F22: =IF(OR(D22="Yes",E22="Yes"),"Eliminated", IF(OR(D22="Automated",E22="Automated"),"Automated Script", IF(AND(D22="No",E22="No"),"Questionnaire",""))) -> Automated Script | I22: technique_ids_match
A23: Does the variant generate the same telemetry classes as the control? | B23: 3.1.03 | C23: Telemetry Equivalence | D23: Automated | E23: N/A | F23: =IF(OR(D23="Yes",E23="Yes"),"Eliminated", IF(OR(D23="Automated",E23="Automated"),"Automated Script", IF(AND(D23="No",E23="No"),"Questionnaire",""))) -> Automated Script | I23: telemetry_classes_match
A24: Is there a functionally equivalent telemetry source on the variant OS for each source in the control? | B24: 3.1.04 | C24: Telemetry Equivalence | D24: No | E24: Yes | F24: =IF(OR(D24="Yes",E24="Yes"),"Eliminated", IF(OR(D24="Automated",E24="Automated"),"Automated Script", IF(AND(D24="No",E24="No"),"Questionnaire",""))) -> Eliminated | J24: Insufficient detail about telemetry sources. Current data equates evaluation to "can this activity be detected"/"is telemetry generated"
A25: Does execution of the variant emit events into those sources? | B25: 3.1.05 | C25: Telemetry Equivalence | D25: Yes | F25: =IF(OR(D25="Yes",E25="Yes"),"Eliminated", IF(OR(D25="Automated",E25="Automated"),"Automated Script", IF(AND(D25="No",E25="No"),"Questionnaire",""))) -> Eliminated | J25: Insufficient detail about telemetry sources. Current data equates evaluation to "can this activity be detected"/"is telemetry generated"
A26: Would a detection written for the control have a logically equivalent form on the variant? | B26: 3.1.06 | C26: Telemetry Equivalence | D26: No | E26: No | F26: =IF(OR(D26="Yes",E26="Yes"),"Eliminated", IF(OR(D26="Automated",E26="Automated"),"Automated Script", IF(AND(D26="No",E26="No"),"Questionnaire",""))) -> Questionnaire | K26: Evaluating this question requires understanding the space of detections available on the original OS and corresponding detections on the variant OS, or specialized detection knowledge. Real world detection increasingly relies on behavioral analysis and it may be possible to implement something similar with this.
A27: Would that detection have an opportunity to fire on the variant’s telemetry? | B27: 3.1.07 | C27: Telemetry Equivalence | D27: No | E27: Yes | F27: =IF(OR(D27="Yes",E27="Yes"),"Eliminated", IF(OR(D27="Automated",E27="Automated"),"Automated Script", IF(AND(D27="No",E27="No"),"Questionnaire",""))) -> Eliminated | J27: Insufficient detail about defender detections. Current data equates evaluation to "can this activity be detected"/"is telemetry generated"
A28: Does the variant preserve the semantic meaning of what the detection observes? | B28: 3.1.08 | C28: Telemetry Equivalence | D28: No | E28: No | F28: =IF(OR(D28="Yes",E28="Yes"),"Eliminated", IF(OR(D28="Automated",E28="Automated"),"Automated Script", IF(AND(D28="No",E28="No"),"Questionnaire",""))) -> Questionnaire | K28: There is a need to have a human semantic understanding of the control vs variant's impact. This could potentially be covered by looking at telemetry (for defensive value).
A29: Does execution generate telemetry in more than one telemetry class? | B29: 3.2.01 | C29: Telemetry Richness & Differentiation | D29: Automated | E29: N/A | F29: =IF(OR(D29="Yes",E29="Yes"),"Eliminated", IF(OR(D29="Automated",E29="Automated"),"Automated Script", IF(AND(D29="No",E29="No"),"Questionnaire",""))) -> Automated Script | I29: telemetry_multi_class | K29: For questions measuring telemetry, we only derived the telemetry classes based on the ATT&CK technique referenced and its mapping to D3FEND artifacts. There was no actual telemetry which was analyzed, so these will likely need deeper verification.
A30: Are different stages observable via different telemetry classes? | B30: 3.2.02 | C30: Telemetry Richness & Differentiation | D30: No | E30: Automated | F30: =IF(OR(D30="Yes",E30="Yes"),"Eliminated", IF(OR(D30="Automated",E30="Automated"),"Automated Script", IF(AND(D30="No",E30="No"),"Questionnaire",""))) -> Automated Script | K30: See note for 3.2.01. The idea of this question is to see if defenders can put together a strong storyline of attacker activity with one telemetry class across multiple activites (it may be technically possible to capture multiple outputs from different sources).
A31: Are the telemetry sources appropriate for the observed behavior? | B31: 3.2.03 | C31: Telemetry Richness & Differentiation | D31: Yes | E31: N/A | F31: =IF(OR(D31="Yes",E31="Yes"),"Eliminated", IF(OR(D31="Automated",E31="Automated"),"Automated Script", IF(AND(D31="No",E31="No"),"Questionnaire",""))) -> Eliminated | J31: Insufficient detail about telemetry sources. Current data equates evaluation to "can this activity be detected"/"is telemetry generated"
A32: Are any telemetry sources clearly incidental or unrelated? (No = pass) | B32: 3.2.04 | C32: Telemetry Richness & Differentiation | D32: Yes | E32: N/A | F32: =IF(OR(D32="Yes",E32="Yes"),"Eliminated", IF(OR(D32="Automated",E32="Automated"),"Automated Script", IF(AND(D32="No",E32="No"),"Questionnaire",""))) -> Eliminated | J32: Insufficient detail about telemetry sources. Current data equates evaluation to "can this activity be detected"/"is telemetry generated"
A33: Do multiple telemetry signals reinforce the same behavioral interpretation? | B33: 3.2.05 | C33: Telemetry Richness & Differentiation | D33: Yes | E33: N/A | F33: =IF(OR(D33="Yes",E33="Yes"),"Eliminated", IF(OR(D33="Automated",E33="Automated"),"Automated Script", IF(AND(D33="No",E33="No"),"Questionnaire",""))) -> Eliminated | J33: Insufficient detail about telemetry sources and signals on defender side, as well as the behavior identified in control. Answering this may require a blind defender analysis of telemetry artifacts produced by the control vs the variant to understand what happened. Current data equates evaluation to "can this activity be detected"/"is telemetry generated"
A34: Is the telemetry sufficient to evaluate detection coverage, not just confirm execution? | B34: 3.2.06 | C34: Telemetry Richness & Differentiation | D34: Yes | E34: N/A | F34: =IF(OR(D34="Yes",E34="Yes"),"Eliminated", IF(OR(D34="Automated",E34="Automated"),"Automated Script", IF(AND(D34="No",E34="No"),"Questionnaire",""))) -> Eliminated | J34: Insufficient detail about defender detections. Current data equates evaluation to "can this activity be detected"/"is telemetry generated"
A35: Does the telemetry provide the same level of diversity as the control? | B35: 3.2.07 | C35: Telemetry Richness & Differentiation | D35: Automated | E35: N/A | F35: =IF(OR(D35="Yes",E35="Yes"),"Eliminated", IF(OR(D35="Automated",E35="Automated"),"Automated Script", IF(AND(D35="No",E35="No"),"Questionnaire",""))) -> Automated Script | I35: telemetry_diversity | K35: See note for 3.2.01
A36: Does the telemetry include all telemetry classes present in the control? | B36: 3.2.08 | C36: Telemetry Richness & Differentiation | D36: Yes | E36: N/A | F36: =IF(OR(D36="Yes",E36="Yes"),"Eliminated", IF(OR(D36="Automated",E36="Automated"),"Automated Script", IF(AND(D36="No",E36="No"),"Questionnaire",""))) -> Eliminated | J36: Duplicate, logically equivalent with 3.2.7 and 3.2.9
A37: Are any telemetry classes from the control missing? | B37: 3.2.09 | C37: Telemetry Richness & Differentiation | D37: Automated | E37: N/A | F37: =IF(OR(D37="Yes",E37="Yes"),"Eliminated", IF(OR(D37="Automated",E37="Automated"),"Automated Script", IF(AND(D37="No",E37="No"),"Questionnaire",""))) -> Automated Script | I37: missing_telemetry_classes | K37: See note for 3.2.01
A38: Are additional telemetry classes present in the variant? | B38: 3.2.10 | C38: Telemetry Richness & Differentiation | D38: Automated | E38: N/A | F38: =IF(OR(D38="Yes",E38="Yes"),"Eliminated", IF(OR(D38="Automated",E38="Automated"),"Automated Script", IF(AND(D38="No",E38="No"),"Questionnaire",""))) -> Automated Script | I38: extra_telemetry_classes | K38: See note for 3.2.01
A39: If additional telemetry exists, does it improve detection capability? | B39: 3.2.11 | C39: Telemetry Richness & Differentiation | D39: No | E39: No | F39: =IF(OR(D39="Yes",E39="Yes"),"Eliminated", IF(OR(D39="Automated",E39="Automated"),"Automated Script", IF(AND(D39="No",E39="No"),"Questionnaire",""))) -> Questionnaire | K39: See note for 3.2.01
A40: Does the LLM output explicitly justify missing telemetry? | B40: 3.2.12 | C40: Telemetry Richness & Differentiation | D40: No | E40: Yes | F40: =IF(OR(D40="Yes",E40="Yes"),"Eliminated", IF(OR(D40="Automated",E40="Automated"),"Automated Script", IF(AND(D40="No",E40="No"),"Questionnaire",""))) -> Eliminated | J40: Prompt did not request justification related to telemetry or defender perspective. Further analysis and prompt-engineering is needed to get LLM output to cater to defender telemetry perspective, and may not be relevant to adversary emulation use-case
...

Sheet FinalManualQuestionnaire
A1: Scoring Category | B1: ID | C1: Evaluation Question | D1: Decision if TRUE | E1: Evaluation Steps (Scoring Aid) | F1: Evaluator Determination | G1: Notes/Comments On Scoring | H1: Notes/Comments on Question
A2: Behavior Chain Fidelity | B2: 1.2 | C2: Does the variant preserve the same logical dependencies between steps? | D2: PASS | E2: 1. Extract the logical_dependencies from each control step. (This may be which machine are commands being run on, any accesses required, files created, etc.). 2. Extract the logical_dependencies from each variant step. 3. Does the control_logical_dependencies match/align with the variant_logical_dependencies?
A3: Technical Realism | B3: 2.1 | C3: Do all steps reference real, identifiable commands or tools available on the target platform? | D3: PASS | E3: 1. List all commands/tools referenced in each step. 2. Look up each one; does it exist on the target platform?
A4: Technical Realism | B4: 2.2 | C4: Are all command arguments, flags, and options valid for the referenced tool and execution context? | D4: PASS | E4: 1. Extract all commands and tools from each from each variant step into variant_tools. 2. Build variant_arguments by pulling the arguments/flags/options from each tool/command from the variant. 3. Validate each variant tool exists from an Online Tool Search. 4. Are the commands and arguments for the variant valid for the tool and the OS?
A5: Technical Realism | B5: 2.3 | C5: Does the procedure respect OS-specific constraints and permissions? | D5: PASS | E5: (ONLY if you accept technique-level permission modeling) 1. For each technique_id, look up x_mitre_permissions_required[] in ATT&CK attack-pattern. 2. Derive implied_privilege from command markers you already encode structurally (e.g., a parsed boolean requires_elevation extracted from sudo, service-control APIs, etc.). 3. Compare required vs implied at the technique level.
A6: Technical Realism | B6: 2.4 | C6: Does the procedure avoid Windows-only constructs on non-Windows systems? | D6: PASS | E6: 1. For each step: 2. Identify the OS of the system used in this step. 3. If non-Windows, check step procedure against list of known Windows-only elements. 4. Did any step using a non-Windows platform contain a known Windows-only element?
A7: Technical Realism | B7: 2.5 | C7: Are privilege requirements stated or implied correctly? | D7: PASS | E7: 1. Identify what privilege is specified or required for each variant step. 2. Extract the technique_id from each variant step. 3. Identify what privilege is required for the technique_id from ATT&CK TTPs. *may also explore the tool itself 4. Does the variant_privilege match the technique_privilege?
A8: Telemetry Equivalence | B8: 3.1.06 | C8: Would a detection written for the control have a logically equivalent form on the variant? | D8: PASS | E8: 1. Evaluate the detection in question, distilling its core actions (i.e. rule to block http connections to an arbitrary IP) 2. Using the vernacular of the variant OS, look for a detection on the target platform to achieve that same core action
A9: Telemetry Equivalence | B9: 3.1.08 | C9: Does the variant preserve the semantic meaning of what the detection observes? | D9: PASS | E9: 1. 2. 3. 4. 5. 6.
A10: Telemetry Richness & Differentiation | B10: 3.2.11 | C10: If additional telemetry exists, does it improve detection capability? | D10: PASS | E10: 1. 2. 3. 4. 5. 6.

Sheet AggregatedManualEval
A1: Scoring Category | B1: ID | C1: Evaluation Question | D1: Decision if TRUE | E1: Evaluation Steps (Scoring Aid) | F1: Evaluator Determination 1 | G1: Evaluator Determination 2 | H1: Evaluator Determination 3 | I1: Evaluator Determination 4 | J1: Evaluator Determination 5 | K1: Total PASS Evaluations | L1: Total FAIL Evaluations | M1: Total N/A Responses | N1: Total Responses (evaluation not blank) | O1: PASS rate | P1: FAIL Rate | Q1: N/A Rate
A2: Behavior Chain Fidelity | B2: 1.2 | C2: Does the variant preserve the same logical dependencies between steps? | D2: PASS | E2: 1. Extract the logical_dependencies from each control step. (This may be which machine are commands being run on, any accesses required, files created, etc.). 2. Extract the logical_dependencies from each variant step. 3. Does the control_logical_dependencies match/align with the variant_logical_dependencies? | F2: ='Manual Questionnaire 1'!F3 -> FALSE | G2: ='Manual Questionnaire 2'!F3 -> TRUE-ish | H2: ='Manual Questionnaire 3'!F3 -> FALSE | I2: ='Manual Questionnaire 4'!F3 -> 0 | J2: ='Manual Questionnaire 5'!G2 -> 0 | K2: {=SUMPRODUCT(--((Table4123[[#This Row],[Evaluator Determination 1]:[Evaluator Determination 5]]=TRUE)+ISNUMBER(SEARCH("TRUE",Table4123[[#This Row],[Evaluator Determination 1]:[Evaluator Determination 5]]&""))+ISNUMBER(SEARCH("yes",Table4123[[#This Row],[Evaluator Determination 1]:[Evaluator Determination 5]]&""))+ISNUMBER(SEARCH("PASS",Table4123[[#This Row],[Evaluator Determination 1]:[Evaluator Determination 5]]&""))>0))} -> 1 | L2: {=SUMPRODUCT(--((Table4123[[#This Row],[Evaluator Determination 1]:[Evaluator Determination 5]]=FALSE)+ISNUMBER(SEARCH("FALSE",Table4123[[#This Row],[Evaluator Determination 1]:[Evaluator Determination 5]]&""))+ISNUMBER(SEARCH("no",Table4123[[#This Row],[Evaluator Determination 1]:[Evaluator Determination 5]]&""))+ISNUMBER(SEARCH("FAIL",Table4123[[#This Row],[Evaluator Determination 1]:[Evaluator Determination 5]]&""))>0))} -> 2 | M2: =COUNTIFS(Table4123[[#This Row],[Evaluator Determination 1]:[Evaluator Determination 5]],"n/a") -> 0 | N2: =COUNTIFS(Table4123[[#This Row],[Evaluator Determination 1]:[Evaluator Determination 5]],"<>",Table4123[[#This Row],[Evaluator Determination 1]:[Evaluator Determination 5]],"<>0") -> 3 | O2: =IF(Table4123[[#This Row],[Total Responses (evaluation not blank)]]=0,"",IF(Table4123[[#This Row],[Decision if TRUE]]="PASS",Table4123[[#This Row],[Total PASS Evaluations]]/Table4123[[#This Row],[Total Responses (evaluation not blank)]],1-Table4123[[#This Row],[Total PASS Evaluations]]/Table4123[[#This Row],[Total Responses (evaluation not blank)]])) -> 0.33333333 | P2: =IF(Table4123[[#This Row],[Total Responses (evaluation not blank)]]=0,"",IF(Table4123[[#This Row],[Decision if TRUE]]="PASS",Table4123[[#This Row],[Total FAIL Evaluations]]/Table4123[[#This Row],[Total Responses (evaluation not blank)]],1-Table4123[[#This Row],[Total FAIL Evaluations]]/Table4123[[#This Row],[Total Responses (evaluation not blank)]])) -> 0.66666667 | Q2: =Table4123[[#This Row],[Total N/A Responses]]/5 -> 0
A3: Technical Realism | B3: 2.1 | C3: Do all steps reference real, identifiable commands or tools available on the target platform? | D3: PASS | E3: 1. List all commands/tools referenced in each step. 2. Look up each one; does it exist on the target platform? | F3: ='Manual Questionnaire 1'!F7 -> TRUE | G3: ='Manual Questionnaire 2'!F7 -> TRUE-ish | H3: ='Manual Questionnaire 3'!F7 -> TRUE | I3: ='Manual Questionnaire 4'!F7 -> yes | J3: ='Manual Questionnaire 5'!G3 -> PASS-ish: commands are technically LInux tools and right, but particulars don't match | K3: {=SUMPRODUCT(--((Table4123[[#This Row],[Evaluator Determination 1]:[Evaluator Determination 5]]=TRUE)+ISNUMBER(SEARCH("TRUE",Table4123[[#This Row],[Evaluator Determination 1]:[Evaluator Determination 5]]&""))+ISNUMBER(SEARCH("yes",Table4123[[#This Row],[Evaluator Determination 1]:[Evaluator Determination 5]]&""))+ISNUMBER(SEARCH("PASS",Table4123[[#This Row],[Evaluator Determination 1]:[Evaluator Determination 5]]&""))>0))} -> 5 | L3: {=SUMPRODUCT(--((Table4123[[#This Row],[Evaluator Determination 1]:[Evaluator Determination 5]]=FALSE)+ISNUMBER(SEARCH("FALSE",Table4123[[#This Row],[Evaluator Determination 1]:[Evaluator Determination 5]]&""))+ISNUMBER(SEARCH("no",Table4123[[#This Row],[Evaluator Determination 1]:[Evaluator Determination 5]]&""))+ISNUMBER(SEARCH("FAIL",Table4123[[#This Row],[Evaluator Determination 1]:[Evaluator Determination 5]]&""))>0))} -> 0 | M3: =COUNTIFS(Table4123[[#This Row],[Evaluator Determination 1]:[Evaluator Determination 5]],"n/a") -> 0 | N3: =COUNTIFS(Table4123[[#This Row],[Evaluator Determination 1]:[Evaluator Determination 5]],"<>",Table4123[[#This Row],[Evaluator Determination 1]:[Evaluator Determination 5]],"<>0") -> 5 | O3: =IF(Table4123[[#This Row],[Total Responses (evaluation not blank)]]=0,"",IF(Table4123[[#This Row],[Decision if TRUE]]="PASS",Table4123[[#This Row],[Total PASS Evaluations]]/Table4123[[#This Row],[Total Responses (evaluation not blank)]],1-Table4123[[#This Row],[Total PASS Evaluations]]/Table4123[[#This Row],[Total Responses (evaluation not blank)]])) -> 1 | P3: =IF(Table4123[[#This Row],[Total Responses (evaluation not blank)]]=0,"",IF(Table4123[[#This Row],[Decision if TRUE]]="PASS",Table4123[[#This Row],[Total FAIL Evaluations]]/Table4123[[#This Row],[Total Responses (evaluation not blank)]],1-Table4123[[#This Row],[Total FAIL Evaluations]]/Table4123[[#This Row],[Total Responses (evaluation not blank)]])) -> 0 | Q3: =Table4123[[#This Row],[Total N/A Responses]]/5 -> 0
A4: Technical Realism | B4: 2.2 | C4: Are all command arguments, flags, and options valid for the referenced tool and execution context? | D4: PASS | E4: 1. Extract all commands and tools from each from each variant step into variant_tools. 2. Build variant_arguments by pulling the arguments/flags/options from each tool/command from the variant. 3. Validate each variant tool exists from an Online Tool Search. 4. Are the commands and arguments for the variant valid for the tool and the OS? | F4: ='Manual Questionnaire 1'!F8 -> FALSE | G4: ='Manual Questionnaire 2'!F8 -> TRUE-ish | H4: ='Manual Questionnaire 3'!F8 -> FALSE | I4: ='Manual Questionnaire 4'!F8 -> yes | J4: ='Manual Questionnaire 5'!G4 -> Fail | K4: {=SUMPRODUCT(--((Table4123[[#This Row],[Evaluator Determination 1]:[Evaluator Determination 5]]=TRUE)+ISNUMBER(SEARCH("TRUE",Table4123[[#This Row],[Evaluator Determination 1]:[Evaluator Determination 5]]&""))+ISNUMBER(SEARCH("yes",Table4123[[#This Row],[Evaluator Determination 1]:[Evaluator Determination 5]]&""))+ISNUMBER(SEARCH("PASS",Table4123[[#This Row],[Evaluator Determination 1]:[Evaluator Determination 5]]&""))>0))} -> 2 | L4: {=SUMPRODUCT(--((Table4123[[#This Row],[Evaluator Determination 1]:[Evaluator Determination 5]]=FALSE)+ISNUMBER(SEARCH("FALSE",Table4123[[#This Row],[Evaluator Determination 1]:[Evaluator Determination 5]]&""))+ISNUMBER(SEARCH("no",Table4123[[#This Row],[Evaluator Determination 1]:[Evaluator Determination 5]]&""))+ISNUMBER(SEARCH("FAIL",Table4123[[#This Row],[Evaluator Determination 1]:[Evaluator Determination 5]]&""))>0))} -> 3 | M4: =COUNTIFS(Table4123[[#This Row],[Evaluator Determination 1]:[Evaluator Determination 5]],"n/a") -> 0 | N4: =COUNTIFS(Table4123[[#This Row],[Evaluator Determination 1]:[Evaluator Determination 5]],"<>",Table4123[[#This Row],[Evaluator Determination 1]:[Evaluator Determination 5]],"<>0") -> 5 | O4: =IF(Table4123[[#This Row],[Total Responses (evaluation not blank)]]=0,"",IF(Table4123[[#This Row],[Decision if TRUE]]="PASS",Table4123[[#This Row],[Total PASS Evaluations]]/Table4123[[#This Row],[Total Responses (evaluation not blank)]],1-Table4123[[#This Row],[Total PASS Evaluations]]/Table4123[[#This Row],[Total Responses (evaluation not blank)]])) -> 0.4 | P4: =IF(Table4123[[#This Row],[Total Responses (evaluation not blank)]]=0,"",IF(Table4123[[#This Row],[Decision if TRUE]]="PASS",Table4123[[#This Row],[Total FAIL Evaluations]]/Table4123[[#This Row],[Total Responses (evaluation not blank)]],1-Table4123[[#This Row],[Total FAIL Evaluations]]/Table4123[[#This Row],[Total Responses (evaluation not blank)]])) -> 0.6 | Q4: =Table4123[[#This Row],[Total N/A Responses]]/5 -> 0
A5: Technical Realism | B5: 2.3 | C5: Does the procedure respect OS-specific constraints and permissions? | D5: PASS | E5: (ONLY if you accept technique-level permission modeling) 1. For each technique_id, look up x_mitre_permissions_required[] in ATT&CK attack-pattern. 2. Derive implied_privilege from command markers you already encode structurally (e.g., a parsed boolean requires_elevation extracted from sudo, service-control APIs, etc.). 3. Compare required vs implied at the technique level. | F5: ='Manual Questionnaire 1'!F9 -> FALSE | G5: ='Manual Questionnaire 2'!F9 -> 0 | H5: ='Manual Questionnaire 3'!F9 -> FALSE | I5: ='Manual Questionnaire 4'!F9 -> yes? | J5: ='Manual Questionnaire 5'!G5 -> 0 | K5: {=SUMPRODUCT(--((Table4123[[#This Row],[Evaluator Determination 1]:[Evaluator Determination 5]]=TRUE)+ISNUMBER(SEARCH("TRUE",Table4123[[#This Row],[Evaluator Determination 1]:[Evaluator Determination 5]]&""))+ISNUMBER(SEARCH("yes",Table4123[[#This Row],[Evaluator Determination 1]:[Evaluator Determination 5]]&""))+ISNUMBER(SEARCH("PASS",Table4123[[#This Row],[Evaluator Determination 1]:[Evaluator Determination 5]]&""))>0))} -> 1 | L5: {=SUMPRODUCT(--((Table4123[[#This Row],[Evaluator Determination 1]:[Evaluator Determination 5]]=FALSE)+ISNUMBER(SEARCH("FALSE",Table4123[[#This Row],[Evaluator Determination 1]:[Evaluator Determination 5]]&""))+ISNUMBER(SEARCH("no",Table4123[[#This Row],[Evaluator Determination 1]:[Evaluator Determination 5]]&""))+ISNUMBER(SEARCH("FAIL",Table4123[[#This Row],[Evaluator Determination 1]:[Evaluator Determination 5]]&""))>0))} -> 2 | M5: =COUNTIFS(Table4123[[#This Row],[Evaluator Determination 1]:[Evaluator Determination 5]],"n/a") -> 0 | N5: =COUNTIFS(Table4123[[#This Row],[Evaluator Determination 1]:[Evaluator Determination 5]],"<>",Table4123[[#This Row],[Evaluator Determination 1]:[Evaluator Determination 5]],"<>0") -> 3 | O5: =IF(Table4123[[#This Row],[Total Responses (evaluation not blank)]]=0,"",IF(Table4123[[#This Row],[Decision if TRUE]]="PASS",Table4123[[#This Row],[Total PASS Evaluations]]/Table4123[[#This Row],[Total Responses (evaluation not blank)]],1-Table4123[[#This Row],[Total PASS Evaluations]]/Table4123[[#This Row],[Total Responses (evaluation not blank)]])) -> 0.33333333 | P5: =IF(Table4123[[#This Row],[Total Responses (evaluation not blank)]]=0,"",IF(Table4123[[#This Row],[Decision if TRUE]]="PASS",Table4123[[#This Row],[Total FAIL Evaluations]]/Table4123[[#This Row],[Total Responses (evaluation not blank)]],1-Table4123[[#This Row],[Total FAIL Evaluations]]/Table4123[[#This Row],[Total Responses (evaluation not blank)]])) -> 0.66666667 | Q5: =Table4123[[#This Row],[Total N/A Responses]]/5 -> 0
A6: Technical Realism | B6: 2.4 | C6: Does the procedure avoid Windows-only constructs on non-Windows systems? | D6: PASS | E6: 1. For each step: 2. Identify the OS of the system used in this step. 3. If non-Windows, check step procedure against list of known Windows-only elements. 4. Did any step using a non-Windows platform contain a known Windows-only element? | F6: ='Manual Questionnaire 1'!F10 -> TRUE | G6: ='Manual Questionnaire 2'!F10 -> TRUE | H6: ='Manual Questionnaire 3'!F10 -> FALSE | I6: ='Manual Questionnaire 4'!F10 -> maybe; see comment on 2.2 | J6: ='Manual Questionnaire 5'!G6 -> Fail | K6: {=SUMPRODUCT(--((Table4123[[#This Row],[Evaluator Determination 1]:[Evaluator Determination 5]]=TRUE)+ISNUMBER(SEARCH("TRUE",Table4123[[#This Row],[Evaluator Determination 1]:[Evaluator Determination 5]]&""))+ISNUMBER(SEARCH("yes",Table4123[[#This Row],[Evaluator Determination 1]:[Evaluator Determination 5]]&""))+ISNUMBER(SEARCH("PASS",Table4123[[#This Row],[Evaluator Determination 1]:[Evaluator Determination 5]]&""))>0))} -> 2 | L6: {=SUMPRODUCT(--((Table4123[[#This Row],[Evaluator Determination 1]:[Evaluator Determination 5]]=FALSE)+ISNUMBER(SEARCH("FALSE",Table4123[[#This Row],[Evaluator Determination 1]:[Evaluator Determination 5]]&""))+ISNUMBER(SEARCH("no",Table4123[[#This Row],[Evaluator Determination 1]:[Evaluator Determination 5]]&""))+ISNUMBER(SEARCH("FAIL",Table4123[[#This Row],[Evaluator Determination 1]:[Evaluator Determination 5]]&""))>0))} -> 2 | M6: =COUNTIFS(Table4123[[#This Row],[Evaluator Determination 1]:[Evaluator Determination 5]],"n/a") -> 0 | N6: =COUNTIFS(Table4123[[#This Row],[Evaluator Determination 1]:[Evaluator Determination 5]],"<>",Table4123[[#This Row],[Evaluator Determination 1]:[Evaluator Determination 5]],"<>0") -> 5 | O6: =IF(Table4123[[#This Row],[Total Responses (evaluation not blank)]]=0,"",IF(Table4123[[#This Row],[Decision if TRUE]]="PASS",Table4123[[#This Row],[Total PASS Evaluations]]/Table4123[[#This Row],[Total Responses (evaluation not blank)]],1-Table4123[[#This Row],[Total PASS Evaluations]]/Table4123[[#This Row],[Total Responses (evaluation not blank)]])) -> 0.4 | P6: =IF(Table4123[[#This Row],[Total Responses (evaluation not blank)]]=0,"",IF(Table4123[[#This Row],[Decision if TRUE]]="PASS",Table4123[[#This Row],[Total FAIL Evaluations]]/Table4123[[#This Row],[Total Responses (evaluation not blank)]],1-Table4123[[#This Row],[Total FAIL Evaluations]]/Table4123[[#This Row],[Total Responses (evaluation not blank)]])) -> 0.4 | Q6: =Table4123[[#This Row],[Total N/A Responses]]/5 -> 0
A7: Technical Realism | B7: 2.5 | C7: Are privilege requirements stated or implied correctly? | D7: PASS | E7: 1. Identify what privilege is specified or required for each variant step. 2. Extract the technique_id from each variant step. 3. Identify what privilege is required for the technique_id from ATT&CK TTPs. *may also explore the tool itself 4. Does the variant_privilege match the technique_privilege? | F7: ='Manual Questionnaire 1'!F11 -> FALSE | G7: ='Manual Questionnaire 2'!F11 -> 0 | H7: ='Manual Questionnaire 3'!F11 -> FALSE | I7: ='Manual Questionnaire 4'!F11 -> yes | J7: ='Manual Questionnaire 5'!G7 -> PASS | K7: {=SUMPRODUCT(--((Table4123[[#This Row],[Evaluator Determination 1]:[Evaluator Determination 5]]=TRUE)+ISNUMBER(SEARCH("TRUE",Table4123[[#This Row],[Evaluator Determination 1]:[Evaluator Determination 5]]&""))+ISNUMBER(SEARCH("yes",Table4123[[#This Row],[Evaluator Determination 1]:[Evaluator Determination 5]]&""))+ISNUMBER(SEARCH("PASS",Table4123[[#This Row],[Evaluator Determination 1]:[Evaluator Determination 5]]&""))>0))} -> 2 | L7: {=SUMPRODUCT(--((Table4123[[#This Row],[Evaluator Determination 1]:[Evaluator Determination 5]]=FALSE)+ISNUMBER(SEARCH("FALSE",Table4123[[#This Row],[Evaluator Determination 1]:[Evaluator Determination 5]]&""))+ISNUMBER(SEARCH("no",Table4123[[#This Row],[Evaluator Determination 1]:[Evaluator Determination 5]]&""))+ISNUMBER(SEARCH("FAIL",Table4123[[#This Row],[Evaluator Determination 1]:[Evaluator Determination 5]]&""))>0))} -> 2 | M7: =COUNTIFS(Table4123[[#This Row],[Evaluator Determination 1]:[Evaluator Determination 5]],"n/a") -> 0 | N7: =COUNTIFS(Table4123[[#This Row],[Evaluator Determination 1]:[Evaluator Determination 5]],"<>",Table4123[[#This Row],[Evaluator Determination 1]:[Evaluator Determination 5]],"<>0") -> 4 | O7: =IF(Table4123[[#This Row],[Total Responses (evaluation not blank)]]=0,"",IF(Table4123[[#This Row],[Decision if TRUE]]="PASS",Table4123[[#This Row],[Total PASS Evaluations]]/Table4123[[#This Row],[Total Responses (evaluation not blank)]],1-Table4123[[#This Row],[Total PASS Evaluations]]/Table4123[[#This Row],[Total Responses (evaluation not blank)]])) -> 0.5 | P7: =IF(Table4123[[#This Row],[Total Responses (evaluation not blank)]]=0,"",IF(Table4123[[#This Row],[Decision if TRUE]]="PASS",Table4123[[#This Row],[Total FAIL Evaluations]]/Table4123[[#This Row],[Total Responses (evaluation not blank)]],1-Table4123[[#This Row],[Total FAIL Evaluations]]/Table4123[[#This Row],[Total Responses (evaluation not blank)]])) -> 0.5 | Q7: =Table4123[[#This Row],[Total N/A Responses]]/5 -> 0
A8: Telemetry Equivalence | B8: 3.1.06 | C8: Would a detection written for the control have a logically equivalent form on the variant? | D8: PASS | E8: 1. Evaluate the detection in question, distilling its core actions (i.e. rule to block http connections to an arbitrary IP) 2. Using the vernacular of the variant OS, look for a detection on the target platform to achieve that same core action | F8: ='Manual Questionnaire 1'!F14 -> n/a | G8: ='Manual Questionnaire 2'!F14 -> TRUE-ish | H8: ='Manual Questionnaire 3'!F14 -> TRUE | I8: ='Manual Questionnaire 4'!F14 -> yes | J8: ='Manual Questionnaire 5'!G8 -> PASS-ish | K8: {=SUMPRODUCT(--((Table4123[[#This Row],[Evaluator Determination 1]:[Evaluator Determination 5]]=TRUE)+ISNUMBER(SEARCH("TRUE",Table4123[[#This Row],[Evaluator Determination 1]:[Evaluator Determination 5]]&""))+ISNUMBER(SEARCH("yes",Table4123[[#This Row],[Evaluator Determination 1]:[Evaluator Determination 5]]&""))+ISNUMBER(SEARCH("PASS",Table4123[[#This Row],[Evaluator Determination 1]:[Evaluator Determination 5]]&""))>0))} -> 4 | L8: {=SUMPRODUCT(--((Table4123[[#This Row],[Evaluator Determination 1]:[Evaluator Determination 5]]=FALSE)+ISNUMBER(SEARCH("FALSE",Table4123[[#This Row],[Evaluator Determination 1]:[Evaluator Determination 5]]&""))+ISNUMBER(SEARCH("no",Table4123[[#This Row],[Evaluator Determination 1]:[Evaluator Determination 5]]&""))+ISNUMBER(SEARCH("FAIL",Table4123[[#This Row],[Evaluator Determination 1]:[Evaluator Determination 5]]&""))>0))} -> 0 | M8: =COUNTIFS(Table4123[[#This Row],[Evaluator Determination 1]:[Evaluator Determination 5]],"n/a") -> 1 | N8: =COUNTIFS(Table4123[[#This Row],[Evaluator Determination 1]:[Evaluator Determination 5]],"<>",Table4123[[#This Row],[Evaluator Determination 1]:[Evaluator Determination 5]],"<>0") -> 5 | O8: =IF(Table4123[[#This Row],[Total Responses (evaluation not blank)]]=0,"",IF(Table4123[[#This Row],[Decision if TRUE]]="PASS",Table4123[[#This Row],[Total PASS Evaluations]]/Table4123[[#This Row],[Total Responses (evaluation not blank)]],1-Table4123[[#This Row],[Total PASS Evaluations]]/Table4123[[#This Row],[Total Responses (evaluation not blank)]])) -> 0.8 | P8: =IF(Table4123[[#This Row],[Total Responses (evaluation not blank)]]=0,"",IF(Table4123[[#This Row],[Decision if TRUE]]="PASS",Table4123[[#This Row],[Total FAIL Evaluations]]/Table4123[[#This Row],[Total Responses (evaluation not blank)]],1-Table4123[[#This Row],[Total FAIL Evaluations]]/Table4123[[#This Row],[Total Responses (evaluation not blank)]])) -> 0 | Q8: =Table4123[[#This Row],[Total N/A Responses]]/5 -> 0.2
A9: Telemetry Equivalence | B9: 3.1.08 | C9: Does the variant preserve the semantic meaning of what the detection observes? | D9: PASS | E9: 1. 2. 3. 4. 5. 6. | F9: ='Manual Questionnaire 1'!F16 -> n/a | G9: ='Manual Questionnaire 2'!F16 -> 0 | H9: ='Manual Questionnaire 3'!F16 -> FALSE | I9: ='Manual Questionnaire 4'!F16 -> yes | J9: ='Manual Questionnaire 5'!G9 -> 0 | K9: {=SUMPRODUCT(--((Table4123[[#This Row],[Evaluator Determination 1]:[Evaluator Determination 5]]=TRUE)+ISNUMBER(SEARCH("TRUE",Table4123[[#This Row],[Evaluator Determination 1]:[Evaluator Determination 5]]&""))+ISNUMBER(SEARCH("yes",Table4123[[#This Row],[Evaluator Determination 1]:[Evaluator Determination 5]]&""))+ISNUMBER(SEARCH("PASS",Table4123[[#This Row],[Evaluator Determination 1]:[Evaluator Determination 5]]&""))>0))} -> 1 | L9: {=SUMPRODUCT(--((Table4123[[#This Row],[Evaluator Determination 1]:[Evaluator Determination 5]]=FALSE)+ISNUMBER(SEARCH("FALSE",Table4123[[#This Row],[Evaluator Determination 1]:[Evaluator Determination 5]]&""))+ISNUMBER(SEARCH("no",Table4123[[#This Row],[Evaluator Determination 1]:[Evaluator Determination 5]]&""))+ISNUMBER(SEARCH("FAIL",Table4123[[#This Row],[Evaluator Determination 1]:[Evaluator Determination 5]]&""))>0))} -> 1 | M9: =COUNTIFS(Table4123[[#This Row],[Evaluator Determination 1]:[Evaluator Determination 5]],"n/a") -> 1 | N9: =COUNTIFS(Table4123[[#This Row],[Evaluator Determination 1]:[Evaluator Determination 5]],"<>",Table4123[[#This Row],[Evaluator Determination 1]:[Evaluator Determination 5]],"<>0") -> 3 | O9: =IF(Table4123[[#This Row],[Total Responses (evaluation not blank)]]=0,"",IF(Table4123[[#This Row],[Decision if TRUE]]="PASS",Table4123[[#This Row],[Total PASS Evaluations]]/Table4123[[#This Row],[Total Responses (evaluation not blank)]],1-Table4123[[#This Row],[Total PASS Evaluations]]/Table4123[[#This Row],[Total Responses (evaluation not blank)]])) -> 0.33333333 | P9: =IF(Table4123[[#This Row],[Total Responses (evaluation not blank)]]=0,"",IF(Table4123[[#This Row],[Decision if TRUE]]="PASS",Table4123[[#This Row],[Total FAIL Evaluations]]/Table4123[[#This Row],[Total Responses (evaluation not blank)]],1-Table4123[[#This Row],[Total FAIL Evaluations]]/Table4123[[#This Row],[Total Responses (evaluation not blank)]])) -> 0.33333333 | Q9: =Table4123[[#This Row],[Total N/A Responses]]/5 -> 0.2
A10: Telemetry Richness & Differentiation | B10: 3.2.11 | C10: If additional telemetry exists, does it improve detection capability? | D10: PASS | E10: 1. 2. 3. 4. 5. 6. | F10: ='Manual Questionnaire 1'!F17 -> n/a | G10: ='Manual Questionnaire 2'!F17 -> 0 | H10: ='Manual Questionnaire 3'!F17 -> FALSE | I10: ='Manual Questionnaire 4'!F17 -> n/a | J10: ='Manual Questionnaire 5'!G10 -> 0 | K10: {=SUMPRODUCT(--((Table4123[[#This Row],[Evaluator Determination 1]:[Evaluator Determination 5]]=TRUE)+ISNUMBER(SEARCH("TRUE",Table4123[[#This Row],[Evaluator Determination 1]:[Evaluator Determination 5]]&""))+ISNUMBER(SEARCH("yes",Table4123[[#This Row],[Evaluator Determination 1]:[Evaluator Determination 5]]&""))+ISNUMBER(SEARCH("PASS",Table4123[[#This Row],[Evaluator Determination 1]:[Evaluator Determination 5]]&""))>0))} -> 0 | L10: {=SUMPRODUCT(--((Table4123[[#This Row],[Evaluator Determination 1]:[Evaluator Determination 5]]=FALSE)+ISNUMBER(SEARCH("FALSE",Table4123[[#This Row],[Evaluator Determination 1]:[Evaluator Determination 5]]&""))+ISNUMBER(SEARCH("no",Table4123[[#This Row],[Evaluator Determination 1]:[Evaluator Determination 5]]&""))+ISNUMBER(SEARCH("FAIL",Table4123[[#This Row],[Evaluator Determination 1]:[Evaluator Determination 5]]&""))>0))} -> 1 | M10: =COUNTIFS(Table4123[[#This Row],[Evaluator Determination 1]:[Evaluator Determination 5]],"n/a") -> 2 | N10: =COUNTIFS(Table4123[[#This Row],[Evaluator Determination 1]:[Evaluator Determination 5]],"<>",Table4123[[#This Row],[Evaluator Determination 1]:[Evaluator Determination 5]],"<>0") -> 3 | O10: =IF(Table4123[[#This Row],[Total Responses (evaluation not blank)]]=0,"",IF(Table4123[[#This Row],[Decision if TRUE]]="PASS",Table4123[[#This Row],[Total PASS Evaluations]]/Table4123[[#This Row],[Total Responses (evaluation not blank)]],1-Table4123[[#This Row],[Total PASS Evaluations]]/Table4123[[#This Row],[Total Responses (evaluation not blank)]])) -> 0 | P10: =IF(Table4123[[#This Row],[Total Responses (evaluation not blank)]]=0,"",IF(Table4123[[#This Row],[Decision if TRUE]]="PASS",Table4123[[#This Row],[Total FAIL Evaluations]]/Table4123[[#This Row],[Total Responses (evaluation not blank)]],1-Table4123[[#This Row],[Total FAIL Evaluations]]/Table4123[[#This Row],[Total Responses (evaluation not blank)]])) -> 0.33333333 | Q10: =Table4123[[#This Row],[Total N/A Responses]]/5 -> 0.4
E12: Total Answered (Per Evaluator) | F12: =COUNTIFS(Table4123[Evaluator Determination 1],"<>",Table4123[Evaluator Determination 1],"<>0") -> 9 | G12: =COUNTIFS(Table4123[Evaluator Determination 2],"<>",Table4123[Evaluator Determination 2],"<>0") -> 5 | H12: =COUNTIFS(Table4123[Evaluator Determination 3],"<>",Table4123[Evaluator Determination 3],"<>0") -> 9 | I12: =COUNTIFS(Table4123[Evaluator Determination 4],"<>",Table4123[Evaluator Determination 4],"<>0") -> 8 | J12: =COUNTIFS(Table4123[Evaluator Determination 5],"<>",Table4123[Evaluator Determination 5],"<>0") -> 5
E13: Total FAIL Responses (Per Evaluator) | F13: {=SUMPRODUCT(--((Table4123[Evaluator Determination 1]=FALSE)+ISNUMBER(SEARCH("FALSE",Table4123[Evaluator Determination 1]&""))+ISNUMBER(SEARCH("no",Table4123[Evaluator Determination 1]&""))+ISNUMBER(SEARCH("Fail",Table4123[Evaluator Determination 1]&""))>0))} -> 4 | G13: {=SUMPRODUCT(--((Table4123[Evaluator Determination 2]=FALSE)+ISNUMBER(SEARCH("FALSE",Table4123[Evaluator Determination 2]&""))+ISNUMBER(SEARCH("no",Table4123[Evaluator Determination 2]&""))+ISNUMBER(SEARCH("Fail",Table4123[Evaluator Determination 2]&""))>0))} -> 0 | H13: {=SUMPRODUCT(--((Table4123[Evaluator Determination 3]=FALSE)+ISNUMBER(SEARCH("FALSE",Table4123[Evaluator Determination 3]&""))+ISNUMBER(SEARCH("no",Table4123[Evaluator Determination 3]&""))+ISNUMBER(SEARCH("Fail",Table4123[Evaluator Determination 3]&""))>0))} -> 7 | I13: {=SUMPRODUCT(--((Table4123[Evaluator Determination 4]=FALSE)+ISNUMBER(SEARCH("FALSE",Table4123[Evaluator Determination 4]&""))+ISNUMBER(SEARCH("no",Table4123[Evaluator Determination 4]&""))+ISNUMBER(SEARCH("Fail",Table4123[Evaluator Determination 4]&""))>0))} -> 0 | J13: {=SUMPRODUCT(--((Table4123[Evaluator Determination 5]=FALSE)+ISNUMBER(SEARCH("FALSE",Table4123[Evaluator Determination 5]&""))+ISNUMBER(SEARCH("no",Table4123[Evaluator Determination 5]&""))+ISNUMBER(SEARCH("Fail",Table4123[Evaluator Determination 5]&""))>0))} -> 2
E14: Total PASS Responses (Per Evaluator) | F14: {=SUMPRODUCT(--((Table4123[Evaluator Determination 1]=TRUE)+ISNUMBER(SEARCH("TRUE",Table4123[Evaluator Determination 1]&""))+ISNUMBER(SEARCH("yes",Table4123[Evaluator Determination 1]&""))>0))} -> 2 | G14: {=SUMPRODUCT(--((Table4123[Evaluator Determination 2]=TRUE)+ISNUMBER(SEARCH("TRUE",Table4123[Evaluator Determination 2]&""))+ISNUMBER(SEARCH("yes",Table4123[Evaluator Determination 2]&""))>0))} -> 5 | H14: {=SUMPRODUCT(--((Table4123[Evaluator Determination 3]=TRUE)+ISNUMBER(SEARCH("TRUE",Table4123[Evaluator Determination 3]&""))+ISNUMBER(SEARCH("yes",Table4123[Evaluator Determination 3]&""))>0))} -> 2 | I14: {=SUMPRODUCT(--((Table4123[Evaluator Determination 4]=TRUE)+ISNUMBER(SEARCH("TRUE",Table4123[Evaluator Determination 4]&""))+ISNUMBER(SEARCH("yes",Table4123[Evaluator Determination 4]&""))>0))} -> 6 | J14: {=SUMPRODUCT(--((Table4123[Evaluator Determination 5]=TRUE)+ISNUMBER(SEARCH("TRUE",Table4123[Evaluator Determination 5]&""))+ISNUMBER(SEARCH("yes",Table4123[Evaluator Determination 5]&""))+ISNUMBER(SEARCH("PASS",Table4123[Evaluator Determination 5]&""))>0))} -> 3
E16: Pass Rate Out of Answered (Per Evaluator) | F16: =F14/F12 -> 0.22222222 | G16: =G14/G12 -> 1 | H16: =H14/H12 -> 0.22222222 | I16: =I14/I12 -> 0.75 | J16: =J14/J12 -> 0.6
E17: Pass Rate Out of All (Per Evaluator) | F17: =F14/9 -> 0.22222222 | G17: =G14/9 -> 0.55555556 | H17: =H14/9 -> 0.22222222 | I17: =I14/9 -> 0.66666667 | J17: =J14/9 -> 0.33333333
E18: Fail Rate Out of Answered (Per Evaluator) | F18: =F13/F12 -> 0.44444444 | G18: =G13/G12 -> 0 | H18: =H13/H12 -> 0.77777778 | I18: =I13/I12 -> 0 | J18: =J13/J12 -> 0.4
E19: Fail Rate Out of All (Per Evaluator) | F19: =F13/9 -> 0.44444444 | G19: =G13/9 -> 0 | H19: =H13/9 -> 0.77777778 | I19: =I13/9 -> 0 | J19: =J13/9 -> 0.22222222
E20: Answer Rate (Per Evaluator) | F20: =F12/9 -> 1 | G20: =G12/9 -> 0.55555556 | H20: =H12/9 -> 1 | I20: =I12/9 -> 0.88888889 | J20: =J12/9 -> 0.55555556
E22: SUM of PASS Rate (max = 9): | F22: =SUM(Table4123[PASS rate]) -> 4.1
E23: Aggregated Manual PASS Rate: | F23: =AVERAGE(Table4123[PASS rate]) -> 0.45555556
E24: Aggregated Manual FAIL Rate: | F24: =AVERAGE(Table4123[FAIL Rate]) -> 0.38888889
E25: Aggregated N/A Rate: | F25: =AVERAGE(Table4123[N/A Rate]) -> 0.088888889

Sheet Manual Questionnaire Template
A1: Scoring Category | B1: ID | C1: Evaluation Question | D1: Authoritative Data Sources (Scoring Aid) | E1: Evaluation Steps (Scoring Aid) | F1: Evaluator Determination | G1: Notes/Comments On Scoring | H1: Notes/Comments on Question
A2: Behavior Chain Fidelity | B2: 1.1 | C2: Does the variant preserve the same ordered sequence of high-level steps as the control? | D2: MITRE ATT&CK STIX: attack-pattern.external_references[].external_id | E2: 1. Extract technique_id from each control step. 2. Validate each technique_id exists in ATT&CK STIX external_id. 3. Build control_step_set = set(canonical_step_id). 4. Extract technique_id from each variant step. 5. Build variant_step_set. 6. Does the control technique_id and canonical_step_id for all the steps align with the variant technique_id and canonical_step_id?
A3: Behavior Chain Fidelity | B3: 1.2 | C3: Does the variant preserve the same logical dependencies between steps? | E3: 1. Extract the logical_dependencies from each control step. (This may be which machine are commands being run on, any accesses required, files created, etc.). 2. Extract the logical_dependencies from each variant step. 3. Does the control_logical_dependencies match/align with the variant_logical_dependencies?
A4: Behavior Chain Fidelity | B4: 1.3 | C4: Does the variant preserve the same operator intent per step? | E4: 1. 2. 3. 4. 5. 6.
A5: Behavior Chain Fidelity | B5: 1.6 | C5: Does the variant preserve the same start and end conditions as the control? | D5: Manual understanding of start and end conditions | E5: 1. Determine start and end conditions in this and the control scenario. 2. Are they the same?
A6: Behavior Chain Fidelity | B6: 1.7 | C6: Does the variant preserve the same privilege context progression as the control? | E6: 1. Determine privilege context of each step in this and the control scenario. 2. Collapse steps with the same context. 3. Compare to control scenario. 4. Is the collapsed list the same as the control scenario's?
A7: Technical Realism | B7: 2.1 | C7: Do all steps reference real, identifiable commands or tools available on the target platform? | E7: 1. List all commands/tools referenced in each step. 2. Look up each one; does it exist on the target platform?
A8: Technical Realism | B8: 2.2 | C8: Are all command arguments, flags, and options valid for the referenced tool and execution context? | E8: 1. Extract all commands and tools from each from each variant step into variant_tools. 2. Build variant_arguments by pulling the arguments/flags/options from each tool/command from the variant. 3. Validate each variant tool exists from an Online Tool Search. 4. Are the commands and arguments for the variant valid for the tool and the OS?
A9: Technical Realism | B9: 2.3 | C9: Does the procedure respect OS-specific constraints and permissions? | D9: Procedure JSON: procedure.step.os, procedure.step.command; ATT&CK STIX (coarse): attack-pattern.x_mitre_permissions_required[] (technique-level only) | E9: (ONLY if you accept technique-level permission modeling) 1. For each technique_id, look up x_mitre_permissions_required[] in ATT&CK attack-pattern. 2. Derive implied_privilege from command markers you already encode structurally (e.g., a parsed boolean requires_elevation extracted from sudo, service-control APIs, etc.). 3. Compare required vs implied at the technique level.
A10: Technical Realism | B10: 2.4 | C10: Does the procedure avoid Windows-only constructs on non-Windows systems? | E10: 1. For each step: 2. Identify the OS of the system used in this step. 3. If non-Windows, check step procedure against list of known Windows-only elements. 4. Did any step using a non-Windows platform contain a known Windows-only element?
A11: Technical Realism | B11: 2.5 | C11: Are privilege requirements stated or implied correctly? | E11: 1. Identify what privilege is specified or required for each variant step. 2. Extract the technique_id from each variant step. 3. Identify what privilege is required for the technique_id from ATT&CK TTPs. *may also explore the tool itself 4. Does the variant_privilege match the technique_privilege?
A12: Defensive Value | B12: 3.0.5 | C12: Does the output surface defender-relevant artifacts? | E12: 1. 2. 3. 4. 5. 6.
A13: Telemetry Equivalence | B13: 3.1.4 | C13: Is there a functionally equivalent telemetry source on the variant OS for each source in the control? | E13: 1. 2. 3. 4. 5. 6.
A14: Telemetry Equivalence | B14: 3.1.6 | C14: Would a detection written for the control have a logically equivalent form on the variant? | E14: 1. Evaluate the detection in question, distilling its core actions (i.e. rule to block http connections to an arbitrary IP) 2. Using the vernacular of the variant OS, look for a detection on the target platform to achieve that same core action
A15: Telemetry Equivalence | B15: 3.1.7 | C15: Would that detection have an opportunity to fire on the variant’s telemetry? | E15: 1. 2. 3. 4. 5. 6.
A16: Telemetry Equivalence | B16: 3.1.8 | C16: Does the variant preserve the semantic meaning of what the detection observes? | E16: 1. 2. 3. 4. 5. 6.
A17: Telemetry Richness & Differentiation | B17: 3.2.11 | C17: If additional telemetry exists, does it improve detection capability? | E17: 1. 2. 3. 4. 5. 6.
A18: Telemetry Richness & Differentiation | B18: 3.2.12 | C18: Does the LLM output explicitly justify missing telemetry? | E18: 1. 2. 3. 4. 5. 6.
A19: Telemetry Richness & Differentiation | B19: 3.2.13 | C19: Does the LLM output explicitly justify additional telemetry? | E19: 1. 2. 3. 4. 5. 6.
A20: Telemetry Richness & Differentiation | B20: 3.2.2 | C20: Are different stages observable via different telemetry classes? | E20: 1. Extract telemetry_classes from each step. 2. Do any 2 consecutive teps have the same telemetry class?

Sheet Manual Questionnaire 5
A1: Scoring Category | B1: ID | C1: Evaluation Question | D1: Authoritative Data Sources (Scoring Aid) | E1: Evaluation Steps (Scoring Aid) | F1: Step or Plan-level evaluation | G1: Evaluator Determination | H1: Notes/Comments On Scoring | I1: Notes/Comments on Question
A2: Behavior Chain Fidelity | B2: 1.2 | C2: Does the variant preserve the same logical dependencies between steps? | E2: 1. Extract the logical_dependencies from each control step. (This may be which machine are commands being run on, any accesses required, files created, etc.). 2. Extract the logical_dependencies from each variant step. 3. Does the control_logical_dependencies match/align with the variant_logical_dependencies?
A3: Technical Realism | B3: 2.1 | C3: Do all steps reference real, identifiable commands or tools available on the target platform? | E3: 1. List all commands/tools referenced in each step. 2. Look up each one; does it exist on the target platform? | F3: Step | G3: PASS-ish: commands are technically LInux tools and right, but particulars don't match | H3: * invokes pwsh which is a *nix tool, but syntax is windows psh * Curl used for file download, but pulls .exe file, a filetype that can't execute. Syntax is right though * Wine to execute downloaded binary - that wouldn't work due to dependencies
A4: Technical Realism | B4: 2.2 | C4: Are all command arguments, flags, and options valid for the referenced tool and execution context? | E4: 1. Extract all commands and tools from each from each variant step into variant_tools. 2. Build variant_arguments by pulling the arguments/flags/options from each tool/command from the variant. 3. Validate each variant tool exists from an Online Tool Search. 4. Are the commands and arguments for the variant valid for the tool and the OS? | F4: step | G4: Fail | H4: Download commands use Windows syntax, downloaded .exe payloads wouldn't work
A5: Technical Realism | B5: 2.3 | C5: Does the procedure respect OS-specific constraints and permissions? | D5: Procedure JSON: procedure.step.os, procedure.step.command; ATT&CK STIX (coarse): attack-pattern.x_mitre_permissions_required[] (technique-level only) | E5: (ONLY if you accept technique-level permission modeling) 1. For each technique_id, look up x_mitre_permissions_required[] in ATT&CK attack-pattern. 2. Derive implied_privilege from command markers you already encode structurally (e.g., a parsed boolean requires_elevation extracted from sudo, service-control APIs, etc.). 3. Compare required vs implied at the technique level. | F5: Plan
A6: Technical Realism | B6: 2.4 | C6: Does the procedure avoid Windows-only constructs on non-Windows systems? | E6: 1. For each step: 2. Identify the OS of the system used in this step. 3. If non-Windows, check step procedure against list of known Windows-only elements. 4. Did any step using a non-Windows platform contain a known Windows-only element? | F6: Step | G6: Fail | H6: References windows-only file formats relying on shoddy, unstable ports of windwos functionality that likely wouldn't work as invocated as if on windows | I6: Powershell for linux exists, but its generally seen to be lacking in terms of features, module support, etc The linux community is frustrated at the lack of commitment from msft on flushing out this offering
A7: Technical Realism | B7: 2.5 | C7: Are privilege requirements stated or implied correctly? | E7: 1. Identify what privilege is specified or required for each variant step. 2. Extract the technique_id from each variant step. 3. Identify what privilege is required for the technique_id from ATT&CK TTPs. *may also explore the tool itself 4. Does the variant_privilege match the technique_privilege? | F7: Step | G7: PASS | H7: All steps from control are unprivileged. We should consider changes of privilege for future testing (local admin -> domain user -> DA)
